Workbook
Name Slicer_Category: #N/A
Name Slicer_Item_Name: #N/A
Name Slicer_Re_order_Level: #N/A
Name Slicer_Supplier: #N/A

Sheet Retail Dashboard
A6: Current Stock (Units) | D6: Inventory Value
A7: =SUM(Table5[Current stock]) -> 506999 | D7: =SUM(Table5[Inventory Value]) -> 4.8846161e+08
A8: Total Quantity Sold | D8: Stock Turnover
A9: =SUM(Table5[Total Qty Sold]) -> 5324 | D9: {=SUM(Table5[Total Revenue])/(SUM(Table5[Current stock]/600))} -> 10724.907

Sheet Inventory master
A1: Item ID | B1: Item Name | C1: Category | D1: Supplier | E1: Unit cost | F1: Unit Price | G1: Re order Level
A2: ITEM001-A | B2: 1x16 PLC Splitter | C2: Splitters | D2: Amphenol | E2: 1186.19 | F2: 1600.45 | G2: 36
A3: ITEM002-A | B3: Mechanical Splicer | C3: Splicers | D3: CommScope | E3: 808.73 | F3: 1190.93 | G3: 48
A4: ITEM003-A | B4: Single-Mode Fiber Cable 200m | C4: Fiber Optic Cables | D4: Belden | E4: 1199.96 | F4: 2088.64 | G4: 88
A5: ITEM004-A | B5: 1x8 PLC Splitter | C5: Splitters | D5: AFL | E5: 9.46 | F5: 17.25 | G5: 49
A6: ITEM005-A | B6: Fiber Adapter | C6: Accessories | D6: Corning Inc. | E6: 1844.49 | F6: 3404.2 | G6: 81
A7: ITEM006-A | B7: Fixed Attenuator 20dB | C7: Attenuators | D7: Corning Inc. | E7: 876.82 | F7: 1454.17 | G7: 93
A8: ITEM007-A | B8: Fusion Splicer | C8: Splicers | D8: Siemon | E8: 435.21 | F8: 846.51 | G8: 52
A9: ITEM008-A | B9: Mechanical Splicer | C9: Splicers | D9: CommScope | E9: 839.56 | F9: 1141.41 | G9: 54
A10: ITEM009-A | B10: 48-Port Fiber Patch Panel | C10: Patch Panels | D10: CommScope | E10: 494.2 | F10: 865.62 | G10: 43
A11: ITEM010-A | B11: 96-Port Fiber Patch Panel | C11: Patch Panels | D11: AFL | E11: 197.97 | F11: 277.51 | G11: 79
A12: ITEM011-A | B12: QSFP28 Transceiver | C12: Transceivers | D12: HellermannTyton | E12: 622.51 | F12: 852.41 | G12: 64
A13: ITEM012-A | B13: 12-Port Fiber Patch Panel | C13: Patch Panels | D13: Huber+Suhner | E13: 1245.47 | F13: 1515.52 | G13: 39
... A17: ITEM016-A | B17: 1x2 PLC Splitter | C17: Splitters | D17: Belden | E17: 205.86 | F17: 256.58 | G17: 55
A18: ITEM017-A | B18: Mechanical Splicer | C18: Splicers | D18: TE Connectivity | E18: 1484.52 | F18: 2666.95 | G18: 14
A19: ITEM018-A | B19: MTP UPC Connector | C19: Connectors | D19: AFL | E19: 1714.17 | F19: 2046.34 | G19: 45
A20: ITEM019-A | B20: 24-Port Fiber Patch Panel | C20: Patch Panels | D20: TE Connectivity | E20: 1773.05 | F20: 3098.97 | G20: 45
A21: ITEM020-A | B21: 96-Port Fiber Patch Panel | C21: Patch Panels | D21: Prysmian Group | E21: 577.51 | F21: 1028.16 | G21: 47
A22: ITEM021-A | B22: Fusion Splicer | C22: Splicers | D22: Corning Inc. | E22: 1448.33 | F22: 2578.14 | G22: 59
A23: ITEM022-A | B23: CFP Transceiver | C23: Transceivers | D23: Panduit | E23: 737.06 | F23: 844.2 | G23: 50
A24: ITEM023-A | B24: 1x2 PLC Splitter | C24: Splitters | D24: Siemon | E24: 839.54 | F24: 1239.65 | G24: 28
A25: ITEM024-A | B25: 1x32 PLC Splitter | C25: Splitters | D25: TE Connectivity | E25: 181.76 | F25: 301.07 | G25: 49
A26: ITEM025-A | B26: 48-Port Fiber Patch Panel | C26: Patch Panels | D26: Prysmian Group | E26: 996.3 | F26: 1436.94 | G26: 33
A27: ITEM026-A | B27: FC APC Connector | C27: Connectors | D27: AFL | E27: 630.68 | F27: 1168.53 | G27: 16
A28: ITEM027-A | B28: Armored Fiber Cable 200m | C28: Fiber Optic Cables | D28: Leviton | E28: 1075.74 | F28: 1742.62 | G28: 15
A29: ITEM028-A | B29: ST UPC Connector | C29: Connectors | D29: Prysmian Group | E29: 1249.66 | F29: 1832.34 | G29: 20
... A575: ITEM574-A | B575: ST APC Connector | C575: Connectors | D575: Leviton | E575: 394.32 | F575: 732.85 | G575: 58
A576: ITEM575-A | B576: Fusion Splicer | C576: Splicers | D576: Belden | E576: 1166.22 | F576: 2262.65 | G576: 17
A577: ITEM576-A | B577: Fusion Splicer | C577: Splicers | D577: Siemon | E577: 1075.34 | F577: 1659.57 | G577: 51
A578: ITEM577-A | B578: 48-Port Fiber Patch Panel | C578: Patch Panels | D578: Panduit | E578: 1178.28 | F578: 1470.76 | G578: 40
A579: ITEM578-A | B579: CFP Transceiver | C579: Transceivers | D579: TE Connectivity | E579: 258.25 | F579: 297.2 | G579: 47
A580: ITEM579-A | B580: Fiber Pigtail | C580: Accessories | D580: Belden | E580: 365.18 | F580: 560.56 | G580: 29
A581: ITEM580-A | B581: Mechanical Splicer | C581: Splicers | D581: TE Connectivity | E581: 1023.55 | F581: 1836.64 | G581: 93
A582: ITEM581-A | B582: Fixed Attenuator 5dB | C582: Attenuators | D582: CommScope | E582: 1307.17 | F582: 1515.58 | G582: 24
A583: ITEM582-A | B583: Fixed Attenuator 10dB | C583: Attenuators | D583: Amphenol | E583: 1965.61 | F583: 2418.8 | G583: 95
A584: ITEM583-A | B584: Fiber Pigtail | C584: Accessories | D584: Huber+Suhner | E584: 38.08 | F584: 58.81 | G584: 80
A585: ITEM584-A | B585: Fiber Optic Tester | C585: Tools | D585: Amphenol | E585: 886.72 | F585: 1222.36 | G585: 63
A586: ITEM585-A | B586: Fusion Splicer | C586: Splicers | D586: Prysmian Group | E586: 1869.43 | F586: 3035.66 | G586: 56
A587: ITEM586-A | B587: 48-Port Fiber Patch Panel | C587: Patch Panels | D587: CommScope | E587: 731.57 | F587: 1355.51 | G587: 60
A588: ITEM587-A | B588: 12-Port Fiber Patch Panel | C588: Patch Panels | D588: Belden | E588: 101.13 | F588: 157.76 | G588: 80
...

Sheet Opening stock
A1: Item ID | B1: ItemName | C1: Category | D1: Supplier | E1: Opening Qty
A2: ITEM001-A | B2: 1x16 PLC Splitter | C2: Splitters | D2: Amphenol | E2: ='Inventory master'!G2*2*7.5 -> 540
A3: ITEM002-A | B3: Mechanical Splicer | C3: Splicers | D3: CommScope | E3: ='Inventory master'!G3*2*7.5 -> 720
A4: ITEM003-A | B4: Single-Mode Fiber Cable 200m | C4: Fiber Optic Cables | D4: Belden | E4: ='Inventory master'!G4*2*7.5 -> 1320
A5: ITEM004-A | B5: 1x8 PLC Splitter | C5: Splitters | D5: AFL | E5: ='Inventory master'!G5*2*7.5 -> 735
A6: ITEM005-A | B6: Fiber Adapter | C6: Accessories | D6: Corning Inc. | E6: ='Inventory master'!G6*2*7.5 -> 1215
A7: ITEM006-A | B7: Fixed Attenuator 20dB | C7: Attenuators | D7: Corning Inc. | E7: ='Inventory master'!G7*2*7.5 -> 1395
A8: ITEM007-A | B8: Fusion Splicer | C8: Splicers | D8: Siemon | E8: ='Inventory master'!G8*2*7.5 -> 780
A9: ITEM008-A | B9: Mechanical Splicer | C9: Splicers | D9: CommScope | E9: ='Inventory master'!G9*2*7.5 -> 810
A10: ITEM009-A | B10: 48-Port Fiber Patch Panel | C10: Patch Panels | D10: CommScope | E10: ='Inventory master'!G10*2*7.5 -> 645
A11: ITEM010-A | B11: 96-Port Fiber Patch Panel | C11: Patch Panels | D11: AFL | E11: ='Inventory master'!G11*2*7.5 -> 1185
A12: ITEM011-A | B12: QSFP28 Transceiver | C12: Transceivers | D12: HellermannTyton | E12: ='Inventory master'!G12*2*7.5 -> 960
A13: ITEM012-A | B13: 12-Port Fiber Patch Panel | C13: Patch Panels | D13: Huber+Suhner | E13: ='Inventory master'!G13*2*7.5 -> 585
... A601: ITEM600-A | B601: Fiber Jumper | C601: Accessories | D601: Belden | E601: ='Inventory master'!G601*2*7.5 -> 795

Sheet Sales 
A1: Sales ID | B1: Date | C1: Item ID | D1: Quantity
A2: SALE001 | B2: 45946 | C2: ITEM115-A | D2: 100
A3: SALE002 | B3: 45542 | C3: ITEM229-A | D3: 4
A4: SALE003 | B4: 45984 | C4: ITEM559-A | D4: 14
A5: SALE004 | B5: 45324 | C5: ITEM031-A | D5: 8
A6: SALE005 | B6: 45809 | C6: ITEM028-A | D6: 18
A7: SALE006 | B7: 45721 | C7: ITEM226-A | D7: 9
A8: SALE007 | B8: 45298 | C8: ITEM164-A | D8: 11
A9: SALE008 | B9: 45576 | C9: ITEM160-A | D9: 50
A10: SALE009 | B10: 45396 | C10: ITEM095-A | D10: 12
A11: SALE010 | B11: 45644 | C11: ITEM271-A | D11: 38
A12: SALE011 | B12: 45891 | C12: ITEM342-A | D12: 7
A13: SALE012 | B13: 45891 | C13: ITEM001-A | D13: 100
... A605: SALE604 | B605: 45833 | C605: ITEM003-A | D605: 100

Sheet Purchases
A1: Purchase ID | B1: Date | C1: Item ID | D1: Quantity Purchased
A2: PUR001 | B2: 45946 | C2: ITEM115-A | D2: 400
A3: PUR002 | B3: 45573 | C3: ITEM251-A | D3: 2
A4: PUR003 | B4: 46046 | C4: ITEM105-A | D4: 8
A5: PUR004 | B5: 45850 | C5: ITEM090-A | D5: 7
A6: PUR005 | B6: 45324 | C6: ITEM031-A | D6: 1
A7: PUR006 | B7: 45530 | C7: ITEM518-A | D7: 7
A8: PUR007 | B8: 45866 | C8: ITEM204-A | D8: 9
A9: PUR008 | B9: 46010 | C9: ITEM559-A | D9: 4
A10: PUR009 | B10: 45751 | C10: ITEM285-A | D10: 11
A11: PUR010 | B11: 45298 | C11: ITEM164-A | D11: 9
A12: PUR011 | B12: 45640 | C12: ITEM285-A | D12: 2
A13: PUR012 | B13: 46073 | C13: ITEM345-A | D13: 1
... A601: PUR600 | B601: 45909 | C601: ITEM437-A | D601: 2

Sheet Inventory calculations
A1: Item ID | B1: Item Name | C1: Category | D1: Supplier | E1: Unit Cost | F1: Unit Price | G1: Re order Level | H1: Opening Stock | I1: Total Qty Sold | J1: Total qty Purchased | K1: Current stock | L1: Stock Validation | M1: Inventory Value | N1: Total Revenue | O1: Last sale Date | P1: Days Since Last Sale | Q1: Reorder Flag | R1: DEADSTOCK FLAG | S1: DEADSTOCK VALUE
A2: ='Inventory master'!A2 -> ITEM001-A | B2: ='Inventory master'!B2 -> 1x16 PLC Splitter | C2: ='Inventory master'!C2 -> Splitters | D2: ='Inventory master'!D2 -> Amphenol | E2: ='Inventory master'!E2 -> 1186.19 | F2: ='Inventory master'!F2 -> 1600.45 | G2: ='Inventory master'!G2 -> 36 | H2: =IFERROR(_xlfn.XLOOKUP(A2, 'Opening stock'!A2:A601, 'Opening stock'!E2:E601), "") -> 540 | I2: =IFERROR(SUMIF(Table3[Item ID],'Inventory calculations'!A2,Table3[Quantity]),0) -> 400 | J2: =IFERROR(SUMIF(Table4[Item ID],'Inventory calculations'!A2,Table4[Quantity Purchased]),0) -> 3 | K2: =H2+J2-I2 -> 143 | L2: =IF(K2<0,"STOCK ISSUE","OK") -> OK | M2: =K2*E2 -> 169625.17 | N2: =Table5[[#This Row],[Total Qty Sold]]*Table5[[#This Row],[Unit Price]] -> 640180 | O2: =IFERROR(_xlfn.MAXIFS(Table3[Date],Table3[Item ID],Table5[[#This Row],[Item ID]]),"") -> 45891 | P2: =IF(Table5[[#This Row],[Last sale Date]]="","Never Sold",TODAY()-Table5[[#This Row],[Last sale Date]]) -> 161 | Q2: =IF(Table5[[#This Row],[Re order Level]]<=Table5[[#This Row],[Current stock]],"ORDERASAP","OK BUT BE CHECKING") -> OK BUT BE CHECKING | R2: =IF(AND(ISNUMBER(B2), B2 > 60), "DEAD", "ACTIVE") -> ACTIVE | S2: =IF(Table5[[#This Row],[DEADSTOCK FLAG]]="DEAD",Table5[[#This Row],[Inventory Value]],0) -> 0
A3: ='Inventory master'!A3 -> ITEM002-A | B3: ='Inventory master'!B3 -> Mechanical Splicer | C3: ='Inventory master'!C3 -> Splicers | D3: ='Inventory master'!D3 -> CommScope | E3: ='Inventory master'!E3 -> 808.73 | F3: ='Inventory master'!F3 -> 1190.93 | G3: ='Inventory master'!G3 -> 48 | H3: =IFERROR(_xlfn.XLOOKUP(A3, 'Opening stock'!A3:A602, 'Opening stock'!E3:E602), "") -> 720 | I3: =IFERROR(SUMIF(Table3[Item ID],'Inventory calculations'!A3,Table3[Quantity]),0) -> 100 | J3: =IFERROR(SUMIF(Table4[Item ID],'Inventory calculations'!A3,Table4[Quantity Purchased]),0) -> 0 | K3: =H3+J3-I3 -> 620 | L3: =IF(K3<0,"STOCK ISSUE","OK") -> OK | M3: =K3*E3 -> 501412.6 | N3: =Table5[[#This Row],[Total Qty Sold]]*Table5[[#This Row],[Unit Price]] -> 119093 | O3: =IFERROR(_xlfn.MAXIFS(Table3[Date],Table3[Item ID],Table5[[#This Row],[Item ID]]),"") -> 45832 | P3: =IF(Table5[[#This Row],[Last sale Date]]="","Never Sold",TODAY()-Table5[[#This Row],[Last sale Date]]) -> 220 | Q3: =IF(Table5[[#This Row],[Re order Level]]<=Table5[[#This Row],[Current stock]],"ORDERASAP","OK BUT BE CHECKING") -> OK BUT BE CHECKING | R3: =IF(AND(ISNUMBER(B3), B3 > 60), "DEAD", "ACTIVE") -> ACTIVE | S3: =IF(Table5[[#This Row],[DEADSTOCK FLAG]]="DEAD",Table5[[#This Row],[Inventory Value]],0) -> 0
A4: ='Inventory master'!A4 -> ITEM003-A | B4: ='Inventory master'!B4 -> Single-Mode Fiber Cable 200m | C4: ='Inventory master'!C4 -> Fiber Optic Cables | D4: ='Inventory master'!D4 -> Belden | E4: ='Inventory master'!E4 -> 1199.96 | F4: ='Inventory master'!F4 -> 2088.64 | G4: ='Inventory master'!G4 -> 88 | H4: =IFERROR(_xlfn.XLOOKUP(A4, 'Opening stock'!A4:A603, 'Opening stock'!E4:E603), "") -> 1320 | I4: =IFERROR(SUMIF(Table3[Item ID],'Inventory calculations'!A4,Table3[Quantity]),0) -> 100 | J4: =IFERROR(SUMIF(Table4[Item ID],'Inventory calculations'!A4,Table4[Quantity Purchased]),0) -> 3 | K4: =H4+J4-I4 -> 1223 | L4: =IF(K4<0,"STOCK ISSUE","OK") -> OK | M4: =K4*E4 -> 1467551.1 | N4: =Table5[[#This Row],[Total Qty Sold]]*Table5[[#This Row],[Unit Price]] -> 208864 | O4: =IFERROR(_xlfn.MAXIFS(Table3[Date],Table3[Item ID],Table5[[#This Row],[Item ID]]),"") -> 45833 | P4: =IF(Table5[[#This Row],[Last sale Date]]="","Never Sold",TODAY()-Table5[[#This Row],[Last sale Date]]) -> 219 | Q4: =IF(Table5[[#This Row],[Re order Level]]<=Table5[[#This Row],[Current stock]],"ORDERASAP","OK BUT BE CHECKING") -> OK BUT BE CHECKING | R4: =IF(AND(ISNUMBER(B4), B4 > 60), "DEAD", "ACTIVE") -> ACTIVE | S4: =IF(Table5[[#This Row],[DEADSTOCK FLAG]]="DEAD",Table5[[#This Row],[Inventory Value]],0) -> 0
A5: ='Inventory master'!A5 -> ITEM004-A | B5: ='Inventory master'!B5 -> 1x8 PLC Splitter | C5: ='Inventory master'!C5 -> Splitters | D5: ='Inventory master'!D5 -> AFL | E5: ='Inventory master'!E5 -> 9.46 | F5: ='Inventory master'!F5 -> 17.25 | G5: ='Inventory master'!G5 -> 49 | H5: =IFERROR(_xlfn.XLOOKUP(A5, 'Opening stock'!A5:A604, 'Opening stock'!E5:E604), "") -> 735 | I5: =IFERROR(SUMIF(Table3[Item ID],'Inventory calculations'!A5,Table3[Quantity]),0) -> 0 | J5: =IFERROR(SUMIF(Table4[Item ID],'Inventory calculations'!A5,Table4[Quantity Purchased]),0) -> 0 | K5: =H5+J5-I5 -> 735 | L5: =IF(K5<0,"STOCK ISSUE","OK") -> OK | M5: =K5*E5 -> 6953.1 | N5: =Table5[[#This Row],[Total Qty Sold]]*Table5[[#This Row],[Unit Price]] -> 0 | P5: =IF(Table5[[#This Row],[Last sale Date]]="","Never Sold",TODAY()-Table5[[#This Row],[Last sale Date]]) -> Never Sold | Q5: =IF(Table5[[#This Row],[Re order Level]]<=Table5[[#This Row],[Current stock]],"ORDERASAP","OK BUT BE CHECKING") -> OK BUT BE CHECKING | R5: =IF(AND(ISNUMBER(B5), B5 > 60), "DEAD", "ACTIVE") -> ACTIVE | S5: =IF(Table5[[#This Row],[DEADSTOCK FLAG]]="DEAD",Table5[[#This Row],[Inventory Value]],0) -> 0
A6: ='Inventory master'!A6 -> ITEM005-A | B6: ='Inventory master'!B6 -> Fiber Adapter | C6: ='Inventory master'!C6 -> Accessories | D6: ='Inventory master'!D6 -> Corning Inc. | E6: ='Inventory master'!E6 -> 1844.49 | F6: ='Inventory master'!F6 -> 3404.2 | G6: ='Inventory master'!G6 -> 81 | H6: =IFERROR(_xlfn.XLOOKUP(A6, 'Opening stock'!A6:A605, 'Opening stock'!E6:E605), "") -> 1215 | I6: =IFERROR(SUMIF(Table3[Item ID],'Inventory calculations'!A6,Table3[Quantity]),0) -> 0 | J6: =IFERROR(SUMIF(Table4[Item ID],'Inventory calculations'!A6,Table4[Quantity Purchased]),0) -> 0 | K6: =H6+J6-I6 -> 1215 | L6: =IF(K6<0,"STOCK ISSUE","OK") -> OK | M6: =K6*E6 -> 2241055.4 | N6: =Table5[[#This Row],[Total Qty Sold]]*Table5[[#This Row],[Unit Price]] -> 0 | P6: =IF(Table5[[#This Row],[Last sale Date]]="","Never Sold",TODAY()-Table5[[#This Row],[Last sale Date]]) -> Never Sold | Q6: =IF(Table5[[#This Row],[Re order Level]]<=Table5[[#This Row],[Current stock]],"ORDERASAP","OK BUT BE CHECKING") -> OK BUT BE CHECKING | R6: =IF(AND(ISNUMBER(B6), B6 > 60), "DEAD", "ACTIVE") -> ACTIVE | S6: =IF(Table5[[#This Row],[DEADSTOCK FLAG]]="DEAD",Table5[[#This Row],[Inventory Value]],0) -> 0
A7: ='Inventory master'!A7 -> ITEM006-A | B7: ='Inventory master'!B7 -> Fixed Attenuator 20dB | C7: ='Inventory master'!C7 -> Attenuators | D7: ='Inventory master'!D7 -> Corning Inc. | E7: ='Inventory master'!E7 -> 876.82 | F7: ='Inventory master'!F7 -> 1454.17 | G7: ='Inventory master'!G7 -> 93 | H7: =IFERROR(_xlfn.XLOOKUP(A7, 'Opening stock'!A7:A606, 'Opening stock'!E7:E606), "") -> 1395 | I7: =IFERROR(SUMIF(Table3[Item ID],'Inventory calculations'!A7,Table3[Quantity]),0) -> 0 | J7: =IFERROR(SUMIF(Table4[Item ID],'Inventory calculations'!A7,Table4[Quantity Purchased]),0) -> 0 | K7: =H7+J7-I7 -> 1395 | L7: =IF(K7<0,"STOCK ISSUE","OK") -> OK | M7: =K7*E7 -> 1223163.9 | N7: =Table5[[#This Row],[Total Qty Sold]]*Table5[[#This Row],[Unit Price]] -> 0 | P7: =IF(Table5[[#This Row],[Last sale Date]]="","Never Sold",TODAY()-Table5[[#This Row],[Last sale Date]]) -> Never Sold | Q7: =IF(Table5[[#This Row],[Re order Level]]<=Table5[[#This Row],[Current stock]],"ORDERASAP","OK BUT BE CHECKING") -> OK BUT BE CHECKING | R7: =IF(AND(ISNUMBER(B7), B7 > 60), "DEAD", "ACTIVE") -> ACTIVE | S7: =IF(Table5[[#This Row],[DEADSTOCK FLAG]]="DEAD",Table5[[#This Row],[Inventory Value]],0) -> 0
A8: ='Inventory master'!A8 -> ITEM007-A | B8: ='Inventory master'!B8 -> Fusion Splicer | C8: ='Inventory master'!C8 -> Splicers | D8: ='Inventory master'!D8 -> Siemon | E8: ='Inventory master'!E8 -> 435.21 | F8: ='Inventory master'!F8 -> 846.51 | G8: ='Inventory master'!G8 -> 52 | H8: =IFERROR(_xlfn.XLOOKUP(A8, 'Opening stock'!A8:A607, 'Opening stock'!E8:E607), "") -> 780 | I8: =IFERROR(SUMIF(Table3[Item ID],'Inventory calculations'!A8,Table3[Quantity]),0) -> 0 | J8: =IFERROR(SUMIF(Table4[Item ID],'Inventory calculations'!A8,Table4[Quantity Purchased]),0) -> 2 | K8: =H8+J8-I8 -> 782 | L8: =IF(K8<0,"STOCK ISSUE","OK") -> OK | M8: =K8*E8 -> 340334.22 | N8: =Table5[[#This Row],[Total Qty Sold]]*Table5[[#This Row],[Unit Price]] -> 0 | P8: =IF(Table5[[#This Row],[Last sale Date]]="","Never Sold",TODAY()-Table5[[#This Row],[Last sale Date]]) -> Never Sold | Q8: =IF(Table5[[#This Row],[Re order Level]]<=Table5[[#This Row],[Current stock]],"ORDERASAP","OK BUT BE CHECKING") -> OK BUT BE CHECKING | R8: =IF(AND(ISNUMBER(B8), B8 > 60), "DEAD", "ACTIVE") -> ACTIVE | S8: =IF(Table5[[#This Row],[DEADSTOCK FLAG]]="DEAD",Table5[[#This Row],[Inventory Value]],0) -> 0
A9: ='Inventory master'!A9 -> ITEM008-A | B9: ='Inventory master'!B9 -> Mechanical Splicer | C9: ='Inventory master'!C9 -> Splicers | D9: ='Inventory master'!D9 -> CommScope | E9: ='Inventory master'!E9 -> 839.56 | F9: ='Inventory master'!F9 -> 1141.41 | G9: ='Inventory master'!G9 -> 54 | H9: =IFERROR(_xlfn.XLOOKUP(A9, 'Opening stock'!A9:A608, 'Opening stock'!E9:E608), "") -> 810 | I9: =IFERROR(SUMIF(Table3[Item ID],'Inventory calculations'!A9,Table3[Quantity]),0) -> 0 | J9: =IFERROR(SUMIF(Table4[Item ID],'Inventory calculations'!A9,Table4[Quantity Purchased]),0) -> 6 | K9: =H9+J9-I9 -> 816 | L9: =IF(K9<0,"STOCK ISSUE","OK") -> OK | M9: =K9*E9 -> 685080.96 | N9: =Table5[[#This Row],[Total Qty Sold]]*Table5[[#This Row],[Unit Price]] -> 0 | P9: =IF(Table5[[#This Row],[Last sale Date]]="","Never Sold",TODAY()-Table5[[#This Row],[Last sale Date]]) -> Never Sold | Q9: =IF(Table5[[#This Row],[Re order Level]]<=Table5[[#This Row],[Current stock]],"ORDERASAP","OK BUT BE CHECKING") -> OK BUT BE CHECKING | R9: =IF(AND(ISNUMBER(B9), B9 > 60), "DEAD", "ACTIVE") -> ACTIVE | S9: =IF(Table5[[#This Row],[DEADSTOCK FLAG]]="DEAD",Table5[[#This Row],[Inventory Value]],0) -> 0
A10: ='Inventory master'!A10 -> ITEM009-A | B10: ='Inventory master'!B10 -> 48-Port Fiber Patch Panel | C10: ='Inventory master'!C10 -> Patch Panels | D10: ='Inventory master'!D10 -> CommScope | E10: ='Inventory master'!E10 -> 494.2 | F10: ='Inventory master'!F10 -> 865.62 | G10: ='Inventory master'!G10 -> 43 | H10: =IFERROR(_xlfn.XLOOKUP(A10, 'Opening stock'!A10:A609, 'Opening stock'!E10:E609), "") -> 645 | I10: =IFERROR(SUMIF(Table3[Item ID],'Inventory calculations'!A10,Table3[Quantity]),0) -> 0 | J10: =IFERROR(SUMIF(Table4[Item ID],'Inventory calculations'!A10,Table4[Quantity Purchased]),0) -> 0 | K10: =H10+J10-I10 -> 645 | L10: =IF(K10<0,"STOCK ISSUE","OK") -> OK | M10: =K10*E10 -> 318759 | N10: =Table5[[#This Row],[Total Qty Sold]]*Table5[[#This Row],[Unit Price]] -> 0 | P10: =IF(Table5[[#This Row],[Last sale Date]]="","Never Sold",TODAY()-Table5[[#This Row],[Last sale Date]]) -> Never Sold | Q10: =IF(Table5[[#This Row],[Re order Level]]<=Table5[[#This Row],[Current stock]],"ORDERASAP","OK BUT BE CHECKING") -> OK BUT BE CHECKING | R10: =IF(AND(ISNUMBER(B10), B10 > 60), "DEAD", "ACTIVE") -> ACTIVE | S10: =IF(Table5[[#This Row],[DEADSTOCK FLAG]]="DEAD",Table5[[#This Row],[Inventory Value]],0) -> 0
A11: ='Inventory master'!A11 -> ITEM010-A | B11: ='Inventory master'!B11 -> 96-Port Fiber Patch Panel | C11: ='Inventory master'!C11 -> Patch Panels | D11: ='Inventory master'!D11 -> AFL | E11: ='Inventory master'!E11 -> 197.97 | F11: ='Inventory master'!F11 -> 277.51 | G11: ='Inventory master'!G11 -> 79 | H11: =IFERROR(_xlfn.XLOOKUP(A11, 'Opening stock'!A11:A610, 'Opening stock'!E11:E610), "") -> 1185 | I11: =IFERROR(SUMIF(Table3[Item ID],'Inventory calculations'!A11,Table3[Quantity]),0) -> 0 | J11: =IFERROR(SUMIF(Table4[Item ID],'Inventory calculations'!A11,Table4[Quantity Purchased]),0) -> 0 | K11: =H11+J11-I11 -> 1185 | L11: =IF(K11<0,"STOCK ISSUE","OK") -> OK | M11: =K11*E11 -> 234594.45 | N11: =Table5[[#This Row],[Total Qty Sold]]*Table5[[#This Row],[Unit Price]] -> 0 | P11: =IF(Table5[[#This Row],[Last sale Date]]="","Never Sold",TODAY()-Table5[[#This Row],[Last sale Date]]) -> Never Sold | Q11: =IF(Table5[[#This Row],[Re order Level]]<=Table5[[#This Row],[Current stock]],"ORDERASAP","OK BUT BE CHECKING") -> OK BUT BE CHECKING | R11: =IF(AND(ISNUMBER(B11), B11 > 60), "DEAD", "ACTIVE") -> ACTIVE | S11: =IF(Table5[[#This Row],[DEADSTOCK FLAG]]="DEAD",Table5[[#This Row],[Inventory Value]],0) -> 0
A12: ='Inventory master'!A12 -> ITEM011-A | B12: ='Inventory master'!B12 -> QSFP28 Transceiver | C12: ='Inventory master'!C12 -> Transceivers | D12: ='Inventory master'!D12 -> HellermannTyton | E12: ='Inventory master'!E12 -> 622.51 | F12: ='Inventory master'!F12 -> 852.41 | G12: ='Inventory master'!G12 -> 64 | H12: =IFERROR(_xlfn.XLOOKUP(A12, 'Opening stock'!A12:A611, 'Opening stock'!E12:E611), "") -> 960 | I12: =IFERROR(SUMIF(Table3[Item ID],'Inventory calculations'!A12,Table3[Quantity]),0) -> 0 | J12: =IFERROR(SUMIF(Table4[Item ID],'Inventory calculations'!A12,Table4[Quantity Purchased]),0) -> 0 | K12: =H12+J12-I12 -> 960 | L12: =IF(K12<0,"STOCK ISSUE","OK") -> OK | M12: =K12*E12 -> 597609.6 | N12: =Table5[[#This Row],[Total Qty Sold]]*Table5[[#This Row],[Unit Price]] -> 0 | P12: =IF(Table5[[#This Row],[Last sale Date]]="","Never Sold",TODAY()-Table5[[#This Row],[Last sale Date]]) -> Never Sold | Q12: =IF(Table5[[#This Row],[Re order Level]]<=Table5[[#This Row],[Current stock]],"ORDERASAP","OK BUT BE CHECKING") -> OK BUT BE CHECKING | R12: =IF(AND(ISNUMBER(B12), B12 > 60), "DEAD", "ACTIVE") -> ACTIVE | S12: =IF(Table5[[#This Row],[DEADSTOCK FLAG]]="DEAD",Table5[[#This Row],[Inventory Value]],0) -> 0
A13: ='Inventory master'!A13 -> ITEM012-A | B13: ='Inventory master'!B13 -> 12-Port Fiber Patch Panel | C13: ='Inventory master'!C13 -> Patch Panels | D13: ='Inventory master'!D13 -> Huber+Suhner | E13: ='Inventory master'!E13 -> 1245.47 | F13: ='Inventory master'!F13 -> 1515.52 | G13: ='Inventory master'!G13 -> 39 | H13: =IFERROR(_xlfn.XLOOKUP(A13, 'Opening stock'!A13:A612, 'Opening stock'!E13:E612), "") -> 585 | I13: =IFERROR(SUMIF(Table3[Item ID],'Inventory calculations'!A13,Table3[Quantity]),0) -> 0 | J13: =IFERROR(SUMIF(Table4[Item ID],'Inventory calculations'!A13,Table4[Quantity Purchased]),0) -> 8 | K13: =H13+J13-I13 -> 593 | L13: =IF(K13<0,"STOCK ISSUE","OK") -> OK | M13: =K13*E13 -> 738563.71 | N13: =Table5[[#This Row],[Total Qty Sold]]*Table5[[#This Row],[Unit Price]] -> 0 | P13: =IF(Table5[[#This Row],[Last sale Date]]="","Never Sold",TODAY()-Table5[[#This Row],[Last sale Date]]) -> Never Sold | Q13: =IF(Table5[[#This Row],[Re order Level]]<=Table5[[#This Row],[Current stock]],"ORDERASAP","OK BUT BE CHECKING") -> OK BUT BE CHECKING | R13: =IF(AND(ISNUMBER(B13), B13 > 60), "DEAD", "ACTIVE") -> ACTIVE | S13: =IF(Table5[[#This Row],[DEADSTOCK FLAG]]="DEAD",Table5[[#This Row],[Inventory Value]],0) -> 0
A14: ='Inventory master'!A14 -> ITEM013-A | B14: ='Inventory master'!B14 -> LC APC Connector | C14: ='Inventory master'!C14 -> Connectors | D14: ='Inventory master'!D14 -> Siemon | E14: ='Inventory master'!E14 -> 332.17 | F14: ='Inventory master'!F14 -> 567.28 | G14: ='Inventory master'!G14 -> 84 | H14: =IFERROR(_xlfn.XLOOKUP(A14, 'Opening stock'!A14:A613, 'Opening stock'!E14:E613), "") -> 1260 | I14: =IFERROR(SUMIF(Table3[Item ID],'Inventory calculations'!A14,Table3[Quantity]),0) -> 0 | J14: =IFERROR(SUMIF(Table4[Item ID],'Inventory calculations'!A14,Table4[Quantity Purchased]),0) -> 0 | K14: =H14+J14-I14 -> 1260 | L14: =IF(K14<0,"STOCK ISSUE","OK") -> OK | M14: =K14*E14 -> 418534.2 | N14: =Table5[[#This Row],[Total Qty Sold]]*Table5[[#This Row],[Unit Price]] -> 0 | P14: =IF(Table5[[#This Row],[Last sale Date]]="","Never Sold",TODAY()-Table5[[#This Row],[Last sale Date]]) -> Never Sold | Q14: =IF(Table5[[#This Row],[Re order Level]]<=Table5[[#This Row],[Current stock]],"ORDERASAP","OK BUT BE CHECKING") -> OK BUT BE CHECKING | R14: =IF(AND(ISNUMBER(B14), B14 > 60), "DEAD", "ACTIVE") -> ACTIVE | S14: =IF(Table5[[#This Row],[DEADSTOCK FLAG]]="DEAD",Table5[[#This Row],[Inventory Value]],0) -> 0
A15: ='Inventory master'!A15 -> ITEM014-A | B15: ='Inventory master'!B15 -> 1x16 PLC Splitter | C15: ='Inventory master'!C15 -> Splitters | D15: ='Inventory master'!D15 -> HellermannTyton | E15: ='Inventory master'!E15 -> 1172.09 | F15: ='Inventory master'!F15 -> 1796.09 | G15: ='Inventory master'!G15 -> 30 | H15: =IFERROR(_xlfn.XLOOKUP(A15, 'Opening stock'!A15:A614, 'Opening stock'!E15:E614), "") -> 450 | I15: =IFERROR(SUMIF(Table3[Item ID],'Inventory calculations'!A15,Table3[Quantity]),0) -> 0 | J15: =IFERROR(SUMIF(Table4[Item ID],'Inventory calculations'!A15,Table4[Quantity Purchased]),0) -> 0 | K15: =H15+J15-I15 -> 450 | L15: =IF(K15<0,"STOCK ISSUE","OK") -> OK | M15: =K15*E15 -> 527440.5 | N15: =Table5[[#This Row],[Total Qty Sold]]*Table5[[#This Row],[Unit Price]] -> 0 | P15: =IF(Table5[[#This Row],[Last sale Date]]="","Never Sold",TODAY()-Table5[[#This Row],[Last sale Date]]) -> Never Sold | Q15: =IF(Table5[[#This Row],[Re order Level]]<=Table5[[#This Row],[Current stock]],"ORDERASAP","OK BUT BE CHECKING") -> OK BUT BE CHECKING | R15: =IF(AND(ISNUMBER(B15), B15 > 60), "DEAD", "ACTIVE") -> ACTIVE | S15: =IF(Table5[[#This Row],[DEADSTOCK FLAG]]="DEAD",Table5[[#This Row],[Inventory Value]],0) -> 0
A16: ='Inventory master'!A16 -> ITEM015-A | B16: ='Inventory master'!B16 -> Fixed Attenuator 5dB | C16: ='Inventory master'!C16 -> Attenuators | D16: ='Inventory master'!D16 -> Belden | E16: ='Inventory master'!E16 -> 612.21 | F16: ='Inventory master'!F16 -> 798.2 | G16: ='Inventory master'!G16 -> 83 | H16: =IFERROR(_xlfn.XLOOKUP(A16, 'Opening stock'!A16:A615, 'Opening stock'!E16:E615), "") -> 1245 | I16: =IFERROR(SUMIF(Table3[Item ID],'Inventory calculations'!A16,Table3[Quantity]),0) -> 0 | J16: =IFERROR(SUMIF(Table4[Item ID],'Inventory calculations'!A16,Table4[Quantity Purchased]),0) -> 3 | K16: =H16+J16-I16 -> 1248 | L16: =IF(K16<0,"STOCK ISSUE","OK") -> OK | M16: =K16*E16 -> 764038.08 | N16: =Table5[[#This Row],[Total Qty Sold]]*Table5[[#This Row],[Unit Price]] -> 0 | P16: =IF(Table5[[#This Row],[Last sale Date]]="","Never Sold",TODAY()-Table5[[#This Row],[Last sale Date]]) -> Never Sold | Q16: =IF(Table5[[#This Row],[Re order Level]]<=Table5[[#This Row],[Current stock]],"ORDERASAP","OK BUT BE CHECKING") -> OK BUT BE CHECKING | R16: =IF(AND(ISNUMBER(B16), B16 > 60), "DEAD", "ACTIVE") -> ACTIVE | S16: =IF(Table5[[#This Row],[DEADSTOCK FLAG]]="DEAD",Table5[[#This Row],[Inventory Value]],0) -> 0
... A25: ='Inventory master'!A25 -> ITEM024-A | B25: ='Inventory master'!B25 -> 1x32 PLC Splitter | C25: ='Inventory master'!C25 -> Splitters | D25: ='Inventory master'!D25 -> TE Connectivity | E25: ='Inventory master'!E25 -> 181.76 | F25: ='Inventory master'!F25 -> 301.07 | G25: ='Inventory master'!G25 -> 49 | H25: =IFERROR(_xlfn.XLOOKUP(A25, 'Opening stock'!A25:A624, 'Opening stock'!E25:E624), "") -> 735 | I25: =IFERROR(SUMIF(Table3[Item ID],'Inventory calculations'!A25,Table3[Quantity]),0) -> 0 | J25: =IFERROR(SUMIF(Table4[Item ID],'Inventory calculations'!A25,Table4[Quantity Purchased]),0) -> 0 | K25: =H25+J25-I25 -> 735 | L25: =IF(K25<0,"STOCK ISSUE","OK") -> OK | M25: =K25*E25 -> 133593.6 | N25: =Table5[[#This Row],[Total Qty Sold]]*Table5[[#This Row],[Unit Price]] -> 0 | P25: =IF(Table5[[#This Row],[Last sale Date]]="","Never Sold",TODAY()-Table5[[#This Row],[Last sale Date]]) -> Never Sold | Q25: =IF(Table5[[#This Row],[Re order Level]]<=Table5[[#This Row],[Current stock]],"ORDERASAP","OK BUT BE CHECKING") -> OK BUT BE CHECKING | R25: =IF(AND(ISNUMBER(B25), B25 > 60), "DEAD", "ACTIVE") -> ACTIVE | S25: =IF(Table5[[#This Row],[DEADSTOCK FLAG]]="DEAD",Table5[[#This Row],[Inventory Value]],0) -> 0
A26: ='Inventory master'!A26 -> ITEM025-A | B26: ='Inventory master'!B26 -> 48-Port Fiber Patch Panel | C26: ='Inventory master'!C26 -> Patch Panels | D26: ='Inventory master'!D26 -> Prysmian Group | E26: ='Inventory master'!E26 -> 996.3 | F26: ='Inventory master'!F26 -> 1436.94 | G26: ='Inventory master'!G26 -> 33 | H26: =IFERROR(_xlfn.XLOOKUP(A26, 'Opening stock'!A26:A625, 'Opening stock'!E26:E625), "") -> 495 | I26: =IFERROR(SUMIF(Table3[Item ID],'Inventory calculations'!A26,Table3[Quantity]),0) -> 20 | J26: =IFERROR(SUMIF(Table4[Item ID],'Inventory calculations'!A26,Table4[Quantity Purchased]),0) -> 0 | K26: =H26+J26-I26 -> 475 | L26: =IF(K26<0,"STOCK ISSUE","OK") -> OK | M26: =K26*E26 -> 473242.5 | N26: =Table5[[#This Row],[Total Qty Sold]]*Table5[[#This Row],[Unit Price]] -> 28738.8 | O26: =IFERROR(_xlfn.MAXIFS(Table3[Date],Table3[Item ID],Table5[[#This Row],[Item ID]]),"") -> 45333 | P26: =IF(Table5[[#This Row],[Last sale Date]]="","Never Sold",TODAY()-Table5[[#This Row],[Last sale Date]]) -> 719 | Q26: =IF(Table5[[#This Row],[Re order Level]]<=Table5[[#This Row],[Current stock]],"ORDERASAP","OK BUT BE CHECKING") -> OK BUT BE CHECKING | R26: =IF(AND(ISNUMBER(B26), B26 > 60), "DEAD", "ACTIVE") -> ACTIVE | S26: =IF(Table5[[#This Row],[DEADSTOCK FLAG]]="DEAD",Table5[[#This Row],[Inventory Value]],0) -> 0
A27: ='Inventory master'!A27 -> ITEM026-A | B27: ='Inventory master'!B27 -> FC APC Connector | C27: ='Inventory master'!C27 -> Connectors | D27: ='Inventory master'!D27 -> AFL | E27: ='Inventory master'!E27 -> 630.68 | F27: ='Inventory master'!F27 -> 1168.53 | G27: ='Inventory master'!G27 -> 16 | H27: =IFERROR(_xlfn.XLOOKUP(A27, 'Opening stock'!A27:A626, 'Opening stock'!E27:E626), "") -> 240 | I27: =IFERROR(SUMIF(Table3[Item ID],'Inventory calculations'!A27,Table3[Quantity]),0) -> 0 | J27: =IFERROR(SUMIF(Table4[Item ID],'Inventory calculations'!A27,Table4[Quantity Purchased]),0) -> 0 | K27: =H27+J27-I27 -> 240 | L27: =IF(K27<0,"STOCK ISSUE","OK") -> OK | M27: =K27*E27 -> 151363.2 | N27: =Table5[[#This Row],[Total Qty Sold]]*Table5[[#This Row],[Unit Price]] -> 0 | P27: =IF(Table5[[#This Row],[Last sale Date]]="","Never Sold",TODAY()-Table5[[#This Row],[Last sale Date]]) -> Never Sold | Q27: =IF(Table5[[#This Row],[Re order Level]]<=Table5[[#This Row],[Current stock]],"ORDERASAP","OK BUT BE CHECKING") -> OK BUT BE CHECKING | R27: =IF(AND(ISNUMBER(B27), B27 > 60), "DEAD", "ACTIVE") -> ACTIVE | S27: =IF(Table5[[#This Row],[DEADSTOCK FLAG]]="DEAD",Table5[[#This Row],[Inventory Value]],0) -> 0
A28: ='Inventory master'!A28 -> ITEM027-A | B28: ='Inventory master'!B28 -> Armored Fiber Cable 200m | C28: ='Inventory master'!C28 -> Fiber Optic Cables | D28: ='Inventory master'!D28 -> Leviton | E28: ='Inventory master'!E28 -> 1075.74 | F28: ='Inventory master'!F28 -> 1742.62 | G28: ='Inventory master'!G28 -> 15 | H28: =IFERROR(_xlfn.XLOOKUP(A28, 'Opening stock'!A28:A627, 'Opening stock'!E28:E627), "") -> 225 | I28: =IFERROR(SUMIF(Table3[Item ID],'Inventory calculations'!A28,Table3[Quantity]),0) -> 0 | J28: =IFERROR(SUMIF(Table4[Item ID],'Inventory calculations'!A28,Table4[Quantity Purchased]),0) -> 0 | K28: =H28+J28-I28 -> 225 | L28: =IF(K28<0,"STOCK ISSUE","OK") -> OK | M28: =K28*E28 -> 242041.5 | N28: =Table5[[#This Row],[Total Qty Sold]]*Table5[[#This Row],[Unit Price]] -> 0 | P28: =IF(Table5[[#This Row],[Last sale Date]]="","Never Sold",TODAY()-Table5[[#This Row],[Last sale Date]]) -> Never Sold | Q28: =IF(Table5[[#This Row],[Re order Level]]<=Table5[[#This Row],[Current stock]],"ORDERASAP","OK BUT BE CHECKING") -> OK BUT BE CHECKING | R28: =IF(AND(ISNUMBER(B28), B28 > 60), "DEAD", "ACTIVE") -> ACTIVE | S28: =IF(Table5[[#This Row],[DEADSTOCK FLAG]]="DEAD",Table5[[#This Row],[Inventory Value]],0) -> 0
A29: ='Inventory master'!A29 -> ITEM028-A | B29: ='Inventory master'!B29 -> ST UPC Connector | C29: ='Inventory master'!C29 -> Connectors | D29: ='Inventory master'!D29 -> Prysmian Group | E29: ='Inventory master'!E29 -> 1249.66 | F29: ='Inventory master'!F29 -> 1832.34 | G29: ='Inventory master'!G29 -> 20 | H29: =IFERROR(_xlfn.XLOOKUP(A29, 'Opening stock'!A29:A628, 'Opening stock'!E29:E628), "") -> 300 | I29: =IFERROR(SUMIF(Table3[Item ID],'Inventory calculations'!A29,Table3[Quantity]),0) -> 18 | J29: =IFERROR(SUMIF(Table4[Item ID],'Inventory calculations'!A29,Table4[Quantity Purchased]),0) -> 20 | K29: =H29+J29-I29 -> 302 | L29: =IF(K29<0,"STOCK ISSUE","OK") -> OK | M29: =K29*E29 -> 377397.32 | N29: =Table5[[#This Row],[Total Qty Sold]]*Table5[[#This Row],[Unit Price]] -> 32982.12 | O29: =IFERROR(_xlfn.MAXIFS(Table3[Date],Table3[Item ID],Table5[[#This Row],[Item ID]]),"") -> 45809 | P29: =IF(Table5[[#This Row],[Last sale Date]]="","Never Sold",TODAY()-Table5[[#This Row],[Last sale Date]]) -> 243 | Q29: =IF(Table5[[#This Row],[Re order Level]]<=Table5[[#This Row],[Current stock]],"ORDERASAP","OK BUT BE CHECKING") -> OK BUT BE CHECKING | R29: =IF(AND(ISNUMBER(B29), B29 > 60), "DEAD", "ACTIVE") -> ACTIVE | S29: =IF(Table5[[#This Row],[DEADSTOCK FLAG]]="DEAD",Table5[[#This Row],[Inventory Value]],0) -> 0
A30: ='Inventory master'!A30 -> ITEM029-A | B30: ='Inventory master'!B30 -> 12-Port Fiber Patch Panel | C30: ='Inventory master'!C30 -> Patch Panels | D30: ='Inventory master'!D30 -> Corning Inc. | E30: ='Inventory master'!E30 -> 1997.37 | F30: ='Inventory master'!F30 -> 2857.07 | G30: ='Inventory master'!G30 -> 75 | H30: =IFERROR(_xlfn.XLOOKUP(A30, 'Opening stock'!A30:A629, 'Opening stock'!E30:E629), "") -> 1125 | I30: =IFERROR(SUMIF(Table3[Item ID],'Inventory calculations'!A30,Table3[Quantity]),0) -> 0 | J30: =IFERROR(SUMIF(Table4[Item ID],'Inventory calculations'!A30,Table4[Quantity Purchased]),0) -> 0 | K30: =H30+J30-I30 -> 1125 | L30: =IF(K30<0,"STOCK ISSUE","OK") -> OK | M30: =K30*E30 -> 2247041.2 | N30: =Table5[[#This Row],[Total Qty Sold]]*Table5[[#This Row],[Unit Price]] -> 0 | P30: =IF(Table5[[#This Row],[Last sale Date]]="","Never Sold",TODAY()-Table5[[#This Row],[Last sale Date]]) -> Never Sold | Q30: =IF(Table5[[#This Row],[Re order Level]]<=Table5[[#This Row],[Current stock]],"ORDERASAP","OK BUT BE CHECKING") -> OK BUT BE CHECKING | R30: =IF(AND(ISNUMBER(B30), B30 > 60), "DEAD", "ACTIVE") -> ACTIVE | S30: =IF(Table5[[#This Row],[DEADSTOCK FLAG]]="DEAD",Table5[[#This Row],[Inventory Value]],0) -> 0
A31: ='Inventory master'!A31 -> ITEM030-A | B31: ='Inventory master'!B31 -> QSFP Transceiver | C31: ='Inventory master'!C31 -> Transceivers | D31: ='Inventory master'!D31 -> AFL | E31: ='Inventory master'!E31 -> 1197.56 | F31: ='Inventory master'!F31 -> 2143.3 | G31: ='Inventory master'!G31 -> 88 | H31: =IFERROR(_xlfn.XLOOKUP(A31, 'Opening stock'!A31:A630, 'Opening stock'!E31:E630), "") -> 1320 | I31: =IFERROR(SUMIF(Table3[Item ID],'Inventory calculations'!A31,Table3[Quantity]),0) -> 0 | J31: =IFERROR(SUMIF(Table4[Item ID],'Inventory calculations'!A31,Table4[Quantity Purchased]),0) -> 0 | K31: =H31+J31-I31 -> 1320 | L31: =IF(K31<0,"STOCK ISSUE","OK") -> OK | M31: =K31*E31 -> 1580779.2 | N31: =Table5[[#This Row],[Total Qty Sold]]*Table5[[#This Row],[Unit Price]] -> 0 | P31: =IF(Table5[[#This Row],[Last sale Date]]="","Never Sold",TODAY()-Table5[[#This Row],[Last sale Date]]) -> Never Sold | Q31: =IF(Table5[[#This Row],[Re order Level]]<=Table5[[#This Row],[Current stock]],"ORDERASAP","OK BUT BE CHECKING") -> OK BUT BE CHECKING | R31: =IF(AND(ISNUMBER(B31), B31 > 60), "DEAD", "ACTIVE") -> ACTIVE | S31: =IF(Table5[[#This Row],[DEADSTOCK FLAG]]="DEAD",Table5[[#This Row],[Inventory Value]],0) -> 0
A32: ='Inventory master'!A32 -> ITEM031-A | B32: ='Inventory master'!B32 -> 1x8 PLC Splitter | C32: ='Inventory master'!C32 -> Splitters | D32: ='Inventory master'!D32 -> Belden | E32: ='Inventory master'!E32 -> 1807.04 | F32: ='Inventory master'!F32 -> 3164.85 | G32: ='Inventory master'!G32 -> 21 | H32: =IFERROR(_xlfn.XLOOKUP(A32, 'Opening stock'!A32:A631, 'Opening stock'!E32:E631), "") -> 315 | I32: =IFERROR(SUMIF(Table3[Item ID],'Inventory calculations'!A32,Table3[Quantity]),0) -> 8 | J32: =IFERROR(SUMIF(Table4[Item ID],'Inventory calculations'!A32,Table4[Quantity Purchased]),0) -> 1 | K32: =H32+J32-I32 -> 308 | L32: =IF(K32<0,"STOCK ISSUE","OK") -> OK | M32: =K32*E32 -> 556568.32 | N32: =Table5[[#This Row],[Total Qty Sold]]*Table5[[#This Row],[Unit Price]] -> 25318.8 | O32: =IFERROR(_xlfn.MAXIFS(Table3[Date],Table3[Item ID],Table5[[#This Row],[Item ID]]),"") -> 45324 | P32: =IF(Table5[[#This Row],[Last sale Date]]="","Never Sold",TODAY()-Table5[[#This Row],[Last sale Date]]) -> 728 | Q32: =IF(Table5[[#This Row],[Re order Level]]<=Table5[[#This Row],[Current stock]],"ORDERASAP","OK BUT BE CHECKING") -> OK BUT BE CHECKING | R32: =IF(AND(ISNUMBER(B32), B32 > 60), "DEAD", "ACTIVE") -> ACTIVE | S32: =IF(Table5[[#This Row],[DEADSTOCK FLAG]]="DEAD",Table5[[#This Row],[Inventory Value]],0) -> 0
A33: ='Inventory master'!A33 -> ITEM032-A | B33: ='Inventory master'!B33 -> MTP UPC Connector | C33: ='Inventory master'!C33 -> Connectors | D33: ='Inventory master'!D33 -> CommScope | E33: ='Inventory master'!E33 -> 1782.7 | F33: ='Inventory master'!F33 -> 2157.31 | G33: ='Inventory master'!G33 -> 13 | H33: =IFERROR(_xlfn.XLOOKUP(A33, 'Opening stock'!A33:A632, 'Opening stock'!E33:E632), "") -> 195 | I33: =IFERROR(SUMIF(Table3[Item ID],'Inventory calculations'!A33,Table3[Quantity]),0) -> 0 | J33: =IFERROR(SUMIF(Table4[Item ID],'Inventory calculations'!A33,Table4[Quantity Purchased]),0) -> 1 | K33: =H33+J33-I33 -> 196 | L33: =IF(K33<0,"STOCK ISSUE","OK") -> OK | M33: =K33*E33 -> 349409.2 | N33: =Table5[[#This Row],[Total Qty Sold]]*Table5[[#This Row],[Unit Price]] -> 0 | P33: =IF(Table5[[#This Row],[Last sale Date]]="","Never Sold",TODAY()-Table5[[#This Row],[Last sale Date]]) -> Never Sold | Q33: =IF(Table5[[#This Row],[Re order Level]]<=Table5[[#This Row],[Current stock]],"ORDERASAP","OK BUT BE CHECKING") -> OK BUT BE CHECKING | R33: =IF(AND(ISNUMBER(B33), B33 > 60), "DEAD", "ACTIVE") -> ACTIVE | S33: =IF(Table5[[#This Row],[DEADSTOCK FLAG]]="DEAD",Table5[[#This Row],[Inventory Value]],0) -> 0
A34: ='Inventory master'!A34 -> ITEM033-A | B34: ='Inventory master'!B34 -> Fiber Cleaner | C34: ='Inventory master'!C34 -> Accessories | D34: ='Inventory master'!D34 -> Corning Inc. | E34: ='Inventory master'!E34 -> 373.91 | F34: ='Inventory master'!F34 -> 532.56 | G34: ='Inventory master'!G34 -> 59 | H34: =IFERROR(_xlfn.XLOOKUP(A34, 'Opening stock'!A34:A633, 'Opening stock'!E34:E633), "") -> 885 | I34: =IFERROR(SUMIF(Table3[Item ID],'Inventory calculations'!A34,Table3[Quantity]),0) -> 0 | J34: =IFERROR(SUMIF(Table4[Item ID],'Inventory calculations'!A34,Table4[Quantity Purchased]),0) -> 0 | K34: =H34+J34-I34 -> 885 | L34: =IF(K34<0,"STOCK ISSUE","OK") -> OK | M34: =K34*E34 -> 330910.35 | N34: =Table5[[#This Row],[Total Qty Sold]]*Table5[[#This Row],[Unit Price]] -> 0 | P34: =IF(Table5[[#This Row],[Last sale Date]]="","Never Sold",TODAY()-Table5[[#This Row],[Last sale Date]]) -> Never Sold | Q34: =IF(Table5[[#This Row],[Re order Level]]<=Table5[[#This Row],[Current stock]],"ORDERASAP","OK BUT BE CHECKING") -> OK BUT BE CHECKING | R34: =IF(AND(ISNUMBER(B34), B34 > 60), "DEAD", "ACTIVE") -> ACTIVE | S34: =IF(Table5[[#This Row],[DEADSTOCK FLAG]]="DEAD",Table5[[#This Row],[Inventory Value]],0) -> 0
A35: ='Inventory master'!A35 -> ITEM034-A | B35: ='Inventory master'!B35 -> MTP UPC Connector | C35: ='Inventory master'!C35 -> Connectors | D35: ='Inventory master'!D35 -> TE Connectivity | E35: ='Inventory master'!E35 -> 553.01 | F35: ='Inventory master'!F35 -> 625.22 | G35: ='Inventory master'!G35 -> 77 | H35: =IFERROR(_xlfn.XLOOKUP(A35, 'Opening stock'!A35:A634, 'Opening stock'!E35:E634), "") -> 1155 | I35: =IFERROR(SUMIF(Table3[Item ID],'Inventory calculations'!A35,Table3[Quantity]),0) -> 0 | J35: =IFERROR(SUMIF(Table4[Item ID],'Inventory calculations'!A35,Table4[Quantity Purchased]),0) -> 8 | K35: =H35+J35-I35 -> 1163 | L35: =IF(K35<0,"STOCK ISSUE","OK") -> OK | M35: =K35*E35 -> 643150.63 | N35: =Table5[[#This Row],[Total Qty Sold]]*Table5[[#This Row],[Unit Price]] -> 0 | P35: =IF(Table5[[#This Row],[Last sale Date]]="","Never Sold",TODAY()-Table5[[#This Row],[Last sale Date]]) -> Never Sold | Q35: =IF(Table5[[#This Row],[Re order Level]]<=Table5[[#This Row],[Current stock]],"ORDERASAP","OK BUT BE CHECKING") -> OK BUT BE CHECKING | R35: =IF(AND(ISNUMBER(B35), B35 > 60), "DEAD", "ACTIVE") -> ACTIVE | S35: =IF(Table5[[#This Row],[DEADSTOCK FLAG]]="DEAD",Table5[[#This Row],[Inventory Value]],0) -> 0
A36: ='Inventory master'!A36 -> ITEM035-A | B36: ='Inventory master'!B36 -> Fixed Attenuator 15dB | C36: ='Inventory master'!C36 -> Attenuators | D36: ='Inventory master'!D36 -> Leviton | E36: ='Inventory master'!E36 -> 1841.77 | F36: ='Inventory master'!F36 -> 3528.41 | G36: ='Inventory master'!G36 -> 82 | H36: =IFERROR(_xlfn.XLOOKUP(A36, 'Opening stock'!A36:A635, 'Opening stock'!E36:E635), "") -> 1230 | I36: =IFERROR(SUMIF(Table3[Item ID],'Inventory calculations'!A36,Table3[Quantity]),0) -> 0 | J36: =IFERROR(SUMIF(Table4[Item ID],'Inventory calculations'!A36,Table4[Quantity Purchased]),0) -> 6 | K36: =H36+J36-I36 -> 1236 | L36: =IF(K36<0,"STOCK ISSUE","OK") -> OK | M36: =K36*E36 -> 2276427.7 | N36: =Table5[[#This Row],[Total Qty Sold]]*Table5[[#This Row],[Unit Price]] -> 0 | P36: =IF(Table5[[#This Row],[Last sale Date]]="","Never Sold",TODAY()-Table5[[#This Row],[Last sale Date]]) -> Never Sold | Q36: =IF(Table5[[#This Row],[Re order Level]]<=Table5[[#This Row],[Current stock]],"ORDERASAP","OK BUT BE CHECKING") -> OK BUT BE CHECKING | R36: =IF(AND(ISNUMBER(B36), B36 > 60), "DEAD", "ACTIVE") -> ACTIVE | S36: =IF(Table5[[#This Row],[DEADSTOCK FLAG]]="DEAD",Table5[[#This Row],[Inventory Value]],0) -> 0
A37: ='Inventory master'!A37 -> ITEM036-A | B37: ='Inventory master'!B37 -> Fiber Cleaner | C37: ='Inventory master'!C37 -> Accessories | D37: ='Inventory master'!D37 -> Amphenol | E37: ='Inventory master'!E37 -> 220.13 | F37: ='Inventory master'!F37 -> 267.32 | G37: ='Inventory master'!G37 -> 45 | H37: =IFERROR(_xlfn.XLOOKUP(A37, 'Opening stock'!A37:A636, 'Opening stock'!E37:E636), "") -> 675 | I37: =IFERROR(SUMIF(Table3[Item ID],'Inventory calculations'!A37,Table3[Quantity]),0) -> 0 | J37: =IFERROR(SUMIF(Table4[Item ID],'Inventory calculations'!A37,Table4[Quantity Purchased]),0) -> 0 | K37: =H37+J37-I37 -> 675 | L37: =IF(K37<0,"STOCK ISSUE","OK") -> OK | M37: =K37*E37 -> 148587.75 | N37: =Table5[[#This Row],[Total Qty Sold]]*Table5[[#This Row],[Unit Price]] -> 0 | P37: =IF(Table5[[#This Row],[Last sale Date]]="","Never Sold",TODAY()-Table5[[#This Row],[Last sale Date]]) -> Never Sold | Q37: =IF(Table5[[#This Row],[Re order Level]]<=Table5[[#This Row],[Current stock]],"ORDERASAP","OK BUT BE CHECKING") -> OK BUT BE CHECKING | R37: =IF(AND(ISNUMBER(B37), B37 > 60), "DEAD", "ACTIVE") -> ACTIVE | S37: =IF(Table5[[#This Row],[DEADSTOCK FLAG]]="DEAD",Table5[[#This Row],[Inventory Value]],0) -> 0
A38: ='Inventory master'!A38 -> ITEM037-A | B38: ='Inventory master'!B38 -> Fiber Jumper | C38: ='Inventory master'!C38 -> Accessories | D38: ='Inventory master'!D38 -> Corning Inc. | E38: ='Inventory master'!E38 -> 1663.18 | F38: ='Inventory master'!F38 -> 2231.44 | G38: ='Inventory master'!G38 -> 77 | H38: =IFERROR(_xlfn.XLOOKUP(A38, 'Opening stock'!A38:A637, 'Opening stock'!E38:E637), "") -> 1155 | I38: =IFERROR(SUMIF(Table3[Item ID],'Inventory calculations'!A38,Table3[Quantity]),0) -> 0 | J38: =IFERROR(SUMIF(Table4[Item ID],'Inventory calculations'!A38,Table4[Quantity Purchased]),0) -> 0 | K38: =H38+J38-I38 -> 1155 | L38: =IF(K38<0,"STOCK ISSUE","OK") -> OK | M38: =K38*E38 -> 1920972.9 | N38: =Table5[[#This Row],[Total Qty Sold]]*Table5[[#This Row],[Unit Price]] -> 0 | P38: =IF(Table5[[#This Row],[Last sale Date]]="","Never Sold",TODAY()-Table5[[#This Row],[Last sale Date]]) -> Never Sold | Q38: =IF(Table5[[#This Row],[Re order Level]]<=Table5[[#This Row],[Current stock]],"ORDERASAP","OK BUT BE CHECKING") -> OK BUT BE CHECKING | R38: =IF(AND(ISNUMBER(B38), B38 > 60), "DEAD", "ACTIVE") -> ACTIVE | S38: =IF(Table5[[#This Row],[DEADSTOCK FLAG]]="DEAD",Table5[[#This Row],[Inventory Value]],0) -> 0
A39: ='Inventory master'!A39 -> ITEM038-A | B39: ='Inventory master'!B39 -> 1x32 PLC Splitter | C39: ='Inventory master'!C39 -> Splitters | D39: ='Inventory master'!D39 -> AFL | E39: ='Inventory master'!E39 -> 1325.07 | F39: ='Inventory master'!F39 -> 2396.54 | G39: ='Inventory master'!G39 -> 47 | H39: =IFERROR(_xlfn.XLOOKUP(A39, 'Opening stock'!A39:A638, 'Opening stock'!E39:E638), "") -> 705 | I39: =IFERROR(SUMIF(Table3[Item ID],'Inventory calculations'!A39,Table3[Quantity]),0) -> 6 | J39: =IFERROR(SUMIF(Table4[Item ID],'Inventory calculations'!A39,Table4[Quantity Purchased]),0) -> 0 | K39: =H39+J39-I39 -> 699 | L39: =IF(K39<0,"STOCK ISSUE","OK") -> OK | M39: =K39*E39 -> 926223.93 | N39: =Table5[[#This Row],[Total Qty Sold]]*Table5[[#This Row],[Unit Price]] -> 14379.24 | O39: =IFERROR(_xlfn.MAXIFS(Table3[Date],Table3[Item ID],Table5[[#This Row],[Item ID]]),"") -> 45360 | P39: =IF(Table5[[#This Row],[Last sale Date]]="","Never Sold",TODAY()-Table5[[#This Row],[Last sale Date]]) -> 692 | Q39: =IF(Table5[[#This Row],[Re order Level]]<=Table5[[#This Row],[Current stock]],"ORDERASAP","OK BUT BE CHECKING") -> OK BUT BE CHECKING | R39: =IF(AND(ISNUMBER(B39), B39 > 60), "DEAD", "ACTIVE") -> ACTIVE | S39: =IF(Table5[[#This Row],[DEADSTOCK FLAG]]="DEAD",Table5[[#This Row],[Inventory Value]],0) -> 0
A40: ='Inventory master'!A40 -> ITEM039-A | B40: ='Inventory master'!B40 -> Fiber Optic Polisher | C40: ='Inventory master'!C40 -> Tools | D40: ='Inventory master'!D40 -> HellermannTyton | E40: ='Inventory master'!E40 -> 1828.15 | F40: ='Inventory master'!F40 -> 2159.76 | G40: ='Inventory master'!G40 -> 95 | H40: =IFERROR(_xlfn.XLOOKUP(A40, 'Opening stock'!A40:A639, 'Opening stock'!E40:E639), "") -> 1425 | I40: =IFERROR(SUMIF(Table3[Item ID],'Inventory calculations'!A40,Table3[Quantity]),0) -> 0 | J40: =IFERROR(SUMIF(Table4[Item ID],'Inventory calculations'!A40,Table4[Quantity Purchased]),0) -> 0 | K40: =H40+J40-I40 -> 1425 | L40: =IF(K40<0,"STOCK ISSUE","OK") -> OK | M40: =K40*E40 -> 2605113.8 | N40: =Table5[[#This Row],[Total Qty Sold]]*Table5[[#This Row],[Unit Price]] -> 0 | P40: =IF(Table5[[#This Row],[Last sale Date]]="","Never Sold",TODAY()-Table5[[#This Row],[Last sale Date]]) -> Never Sold | Q40: =IF(Table5[[#This Row],[Re order Level]]<=Table5[[#This Row],[Current stock]],"ORDERASAP","OK BUT BE CHECKING") -> OK BUT BE CHECKING | R40: =IF(AND(ISNUMBER(B40), B40 > 60), "DEAD", "ACTIVE") -> ACTIVE | S40: =IF(Table5[[#This Row],[DEADSTOCK FLAG]]="DEAD",Table5[[#This Row],[Inventory Value]],0) -> 0
A41: ='Inventory master'!A41 -> ITEM040-A | B41: ='Inventory master'!B41 -> Fiber Optic Polisher | C41: ='Inventory master'!C41 -> Tools | D41: ='Inventory master'!D41 -> HellermannTyton | E41: ='Inventory master'!E41 -> 1789.47 | F41: ='Inventory master'!F41 -> 3100.56 | G41: ='Inventory master'!G41 -> 84 | H41: =IFERROR(_xlfn.XLOOKUP(A41, 'Opening stock'!A41:A640, 'Opening stock'!E41:E640), "") -> 1260 | I41: =IFERROR(SUMIF(Table3[Item ID],'Inventory calculations'!A41,Table3[Quantity]),0) -> 0 | J41: =IFERROR(SUMIF(Table4[Item ID],'Inventory calculations'!A41,Table4[Quantity Purchased]),0) -> 4 | K41: =H41+J41-I41 -> 1264 | L41: =IF(K41<0,"STOCK ISSUE","OK") -> OK | M41: =K41*E41 -> 2261890.1 | N41: =Table5[[#This Row],[Total Qty Sold]]*Table5[[#This Row],[Unit Price]] -> 0 | P41: =IF(Table5[[#This Row],[Last sale Date]]="","Never Sold",TODAY()-Table5[[#This Row],[Last sale Date]]) -> Never Sold | Q41: =IF(Table5[[#This Row],[Re order Level]]<=Table5[[#This Row],[Current stock]],"ORDERASAP","OK BUT BE CHECKING") -> OK BUT BE CHECKING | R41: =IF(AND(ISNUMBER(B41), B41 > 60), "DEAD", "ACTIVE") -> ACTIVE | S41: =IF(Table5[[#This Row],[DEADSTOCK FLAG]]="DEAD",Table5[[#This Row],[Inventory Value]],0) -> 0
A42: ='Inventory master'!A42 -> ITEM041-A | B42: ='Inventory master'!B42 -> Fusion Splicer | C42: ='Inventory master'!C42 -> Splicers | D42: ='Inventory master'!D42 -> Panduit | E42: ='Inventory master'!E42 -> 237.27 | F42: ='Inventory master'!F42 -> 275.62 | G42: ='Inventory master'!G42 -> 85 | H42: =IFERROR(_xlfn.XLOOKUP(A42, 'Opening stock'!A42:A641, 'Opening stock'!E42:E641), "") -> 1275 | I42: =IFERROR(SUMIF(Table3[Item ID],'Inventory calculations'!A42,Table3[Quantity]),0) -> 0 | J42: =IFERROR(SUMIF(Table4[Item ID],'Inventory calculations'!A42,Table4[Quantity Purchased]),0) -> 21 | K42: =H42+J42-I42 -> 1296 | L42: =IF(K42<0,"STOCK ISSUE","OK") -> OK | M42: =K42*E42 -> 307501.92 | N42: =Table5[[#This Row],[Total Qty Sold]]*Table5[[#This Row],[Unit Price]] -> 0 | P42: =IF(Table5[[#This Row],[Last sale Date]]="","Never Sold",TODAY()-Table5[[#This Row],[Last sale Date]]) -> Never Sold | Q42: =IF(Table5[[#This Row],[Re order Level]]<=Table5[[#This Row],[Current stock]],"ORDERASAP","OK BUT BE CHECKING") -> OK BUT BE CHECKING | R42: =IF(AND(ISNUMBER(B42), B42 > 60), "DEAD", "ACTIVE") -> ACTIVE | S42: =IF(Table5[[#This Row],[DEADSTOCK FLAG]]="DEAD",Table5[[#This Row],[Inventory Value]],0) -> 0
A43: ='Inventory master'!A43 -> ITEM042-A | B43: ='Inventory master'!B43 -> ST UPC Connector | C43: ='Inventory master'!C43 -> Connectors | D43: ='Inventory master'!D43 -> Huber+Suhner | E43: ='Inventory master'!E43 -> 52.07 | F43: ='Inventory master'!F43 -> 76.97 | G43: ='Inventory master'!G43 -> 47 | H43: =IFERROR(_xlfn.XLOOKUP(A43, 'Opening stock'!A43:A642, 'Opening stock'!E43:E642), "") -> 705 | I43: =IFERROR(SUMIF(Table3[Item ID],'Inventory calculations'!A43,Table3[Quantity]),0) -> 0 | J43: =IFERROR(SUMIF(Table4[Item ID],'Inventory calculations'!A43,Table4[Quantity Purchased]),0) -> 10 | K43: =H43+J43-I43 -> 715 | L43: =IF(K43<0,"STOCK ISSUE","OK") -> OK | M43: =K43*E43 -> 37230.05 | N43: =Table5[[#This Row],[Total Qty Sold]]*Table5[[#This Row],[Unit Price]] -> 0 | P43: =IF(Table5[[#This Row],[Last sale Date]]="","Never Sold",TODAY()-Table5[[#This Row],[Last sale Date]]) -> Never Sold | Q43: =IF(Table5[[#This Row],[Re order Level]]<=Table5[[#This Row],[Current stock]],"ORDERASAP","OK BUT BE CHECKING") -> OK BUT BE CHECKING | R43: =IF(AND(ISNUMBER(B43), B43 > 60), "DEAD", "ACTIVE") -> ACTIVE | S43: =IF(Table5[[#This Row],[DEADSTOCK FLAG]]="DEAD",Table5[[#This Row],[Inventory Value]],0) -> 0
A44: ='Inventory master'!A44 -> ITEM043-A | B44: ='Inventory master'!B44 -> Pedestal Enclosure | C44: ='Inventory master'!C44 -> Enclosures | D44: ='Inventory master'!D44 -> CommScope | E44: ='Inventory master'!E44 -> 423.32 | F44: ='Inventory master'!F44 -> 611.2 | G44: ='Inventory master'!G44 -> 71 | H44: =IFERROR(_xlfn.XLOOKUP(A44, 'Opening stock'!A44:A643, 'Opening stock'!E44:E643), "") -> 1065 | I44: =IFERROR(SUMIF(Table3[Item ID],'Inventory calculations'!A44,Table3[Quantity]),0) -> 0 | J44: =IFERROR(SUMIF(Table4[Item ID],'Inventory calculations'!A44,Table4[Quantity Purchased]),0) -> 8 | K44: =H44+J44-I44 -> 1073 | L44: =IF(K44<0,"STOCK ISSUE","OK") -> OK | M44: =K44*E44 -> 454222.36 | N44: =Table5[[#This Row],[Total Qty Sold]]*Table5[[#This Row],[Unit Price]] -> 0 | P44: =IF(Table5[[#This Row],[Last sale Date]]="","Never Sold",TODAY()-Table5[[#This Row],[Last sale Date]]) -> Never Sold | Q44: =IF(Table5[[#This Row],[Re order Level]]<=Table5[[#This Row],[Current stock]],"ORDERASAP","OK BUT BE CHECKING") -> OK BUT BE CHECKING | R44: =IF(AND(ISNUMBER(B44), B44 > 60), "DEAD", "ACTIVE") -> ACTIVE | S44: =IF(Table5[[#This Row],[DEADSTOCK FLAG]]="DEAD",Table5[[#This Row],[Inventory Value]],0) -> 0
A45: ='Inventory master'!A45 -> ITEM044-A | B45: ='Inventory master'!B45 -> Fiber Optic Cutter | C45: ='Inventory master'!C45 -> Tools | D45: ='Inventory master'!D45 -> Amphenol | E45: ='Inventory master'!E45 -> 1153.06 | F45: ='Inventory master'!F45 -> 1402.0 | G45: ='Inventory master'!G45 -> 77 | H45: =IFERROR(_xlfn.XLOOKUP(A45, 'Opening stock'!A45:A644, 'Opening stock'!E45:E644), "") -> 1155 | I45: =IFERROR(SUMIF(Table3[Item ID],'Inventory calculations'!A45,Table3[Quantity]),0) -> 0 | J45: =IFERROR(SUMIF(Table4[Item ID],'Inventory calculations'!A45,Table4[Quantity Purchased]),0) -> 4 | K45: =H45+J45-I45 -> 1159 | L45: =IF(K45<0,"STOCK ISSUE","OK") -> OK | M45: =K45*E45 -> 1336396.5 | N45: =Table5[[#This Row],[Total Qty Sold]]*Table5[[#This Row],[Unit Price]] -> 0 | P45: =IF(Table5[[#This Row],[Last sale Date]]="","Never Sold",TODAY()-Table5[[#This Row],[Last sale Date]]) -> Never Sold | Q45: =IF(Table5[[#This Row],[Re order Level]]<=Table5[[#This Row],[Current stock]],"ORDERASAP","OK BUT BE CHECKING") -> OK BUT BE CHECKING | R45: =IF(AND(ISNUMBER(B45), B45 > 60), "DEAD", "ACTIVE") -> ACTIVE | S45: =IF(Table5[[#This Row],[DEADSTOCK FLAG]]="DEAD",Table5[[#This Row],[Inventory Value]],0) -> 0
A46: ='Inventory master'!A46 -> ITEM045-A | B46: ='Inventory master'!B46 -> Single-Mode Fiber Cable 100m | C46: ='Inventory master'!C46 -> Fiber Optic Cables | D46: ='Inventory master'!D46 -> TE Connectivity | E46: ='Inventory master'!E46 -> 422.48 | F46: ='Inventory master'!F46 -> 786.86 | G46: ='Inventory master'!G46 -> 76 | H46: =IFERROR(_xlfn.XLOOKUP(A46, 'Opening stock'!A46:A645, 'Opening stock'!E46:E645), "") -> 1140 | I46: =IFERROR(SUMIF(Table3[Item ID],'Inventory calculations'!A46,Table3[Quantity]),0) -> 0 | J46: =IFERROR(SUMIF(Table4[Item ID],'Inventory calculations'!A46,Table4[Quantity Purchased]),0) -> 20 | K46: =H46+J46-I46 -> 1160 | L46: =IF(K46<0,"STOCK ISSUE","OK") -> OK | M46: =K46*E46 -> 490076.8 | N46: =Table5[[#This Row],[Total Qty Sold]]*Table5[[#This Row],[Unit Price]] -> 0 | P46: =IF(Table5[[#This Row],[Last sale Date]]="","Never Sold",TODAY()-Table5[[#This Row],[Last sale Date]]) -> Never Sold | Q46: =IF(Table5[[#This Row],[Re order Level]]<=Table5[[#This Row],[Current stock]],"ORDERASAP","OK BUT BE CHECKING") -> OK BUT BE CHECKING | R46: =IF(AND(ISNUMBER(B46), B46 > 60), "DEAD", "ACTIVE") -> ACTIVE | S46: =IF(Table5[[#This Row],[DEADSTOCK FLAG]]="DEAD",Table5[[#This Row],[Inventory Value]],0) -> 0
A47: ='Inventory master'!A47 -> ITEM046-A | B47: ='Inventory master'!B47 -> Mechanical Splicer | C47: ='Inventory master'!C47 -> Splicers | D47: ='Inventory master'!D47 -> AFL | E47: ='Inventory master'!E47 -> 1063.44 | F47: ='Inventory master'!F47 -> 1887.12 | G47: ='Inventory master'!G47 -> 31 | H47: =IFERROR(_xlfn.XLOOKUP(A47, 'Opening stock'!A47:A646, 'Opening stock'!E47:E646), "") -> 465 | I47: =IFERROR(SUMIF(Table3[Item ID],'Inventory calculations'!A47,Table3[Quantity]),0) -> 5 | J47: =IFERROR(SUMIF(Table4[Item ID],'Inventory calculations'!A47,Table4[Quantity Purchased]),0) -> 0 | K47: =H47+J47-I47 -> 460 | L47: =IF(K47<0,"STOCK ISSUE","OK") -> OK | M47: =K47*E47 -> 489182.4 | N47: =Table5[[#This Row],[Total Qty Sold]]*Table5[[#This Row],[Unit Price]] -> 9435.6 | O47: =IFERROR(_xlfn.MAXIFS(Table3[Date],Table3[Item ID],Table5[[#This Row],[Item ID]]),"") -> 45476 | P47: =IF(Table5[[#This Row],[Last sale Date]]="","Never Sold",TODAY()-Table5[[#This Row],[Last sale Date]]) -> 576 | Q47: =IF(Table5[[#This Row],[Re order Level]]<=Table5[[#This Row],[Current stock]],"ORDERASAP","OK BUT BE CHECKING") -> OK BUT BE CHECKING | R47: =IF(AND(ISNUMBER(B47), B47 > 60), "DEAD", "ACTIVE") -> ACTIVE | S47: =IF(Table5[[#This Row],[DEADSTOCK FLAG]]="DEAD",Table5[[#This Row],[Inventory Value]],0) -> 0
A48: ='Inventory master'!A48 -> ITEM047-A | B48: ='Inventory master'!B48 -> QSFP28 Transceiver | C48: ='Inventory master'!C48 -> Transceivers | D48: ='Inventory master'!D48 -> HellermannTyton | E48: ='Inventory master'!E48 -> 1460.91 | F48: ='Inventory master'!F48 -> 1969.33 | G48: ='Inventory master'!G48 -> 67 | H48: =IFERROR(_xlfn.XLOOKUP(A48, 'Opening stock'!A48:A647, 'Opening stock'!E48:E647), "") -> 1005 | I48: =IFERROR(SUMIF(Table3[Item ID],'Inventory calculations'!A48,Table3[Quantity]),0) -> 0 | J48: =IFERROR(SUMIF(Table4[Item ID],'Inventory calculations'!A48,Table4[Quantity Purchased]),0) -> 2 | K48: =H48+J48-I48 -> 1007 | L48: =IF(K48<0,"STOCK ISSUE","OK") -> OK | M48: =K48*E48 -> 1471136.4 | N48: =Table5[[#This Row],[Total Qty Sold]]*Table5[[#This Row],[Unit Price]] -> 0 | P48: =IF(Table5[[#This Row],[Last sale Date]]="","Never Sold",TODAY()-Table5[[#This Row],[Last sale Date]]) -> Never Sold | Q48: =IF(Table5[[#This Row],[Re order Level]]<=Table5[[#This Row],[Current stock]],"ORDERASAP","OK BUT BE CHECKING") -> OK BUT BE CHECKING | R48: =IF(AND(ISNUMBER(B48), B48 > 60), "DEAD", "ACTIVE") -> ACTIVE | S48: =IF(Table5[[#This Row],[DEADSTOCK FLAG]]="DEAD",Table5[[#This Row],[Inventory Value]],0) -> 0
...

Sheet Dashboard tables
A1: Chart 1: Sales Trend Over Time
A2: Row Labels | B2: Sum of Quantity
A3: Jan | B3: 373
A4: Feb | B4: 389
A5: Mar | B5: 463
A6: Apr | B6: 389
A7: May | B7: 363
A8: Jun | B8: 849
A9: Jul | B9: 366
A10: Aug | B10: 499
A11: Sep | B11: 429
A12: Oct | B12: 498
A13: Nov | B13: 369
A14: Dec | B14: 362
A15: Grand Total | B15: 5349
A17: Top-Selling Products
A18: Row Labels | B18: Sum of Total Qty Sold
A19: 12-Port Fiber Patch Panel | B19: 261
A20: 1x16 PLC Splitter | B20: 443
A21: 1x2 PLC Splitter | B21: 0
A22: 1x32 PLC Splitter | B22: 55
A23: 1x4 PLC Splitter | B23: 12
A24: 1x8 PLC Splitter | B24: 132
A25: 24-Port Fiber Patch Panel | B25: 0
A26: 48-Port Fiber Patch Panel | B26: 144
A27: 72-Port Fiber Patch Panel | B27: 163
A28: 96-Port Fiber Patch Panel | B28: 25
A29: Armored Fiber Cable 100m | B29: 0
A30: Armored Fiber Cable 200m | B30: 0
... A91: Grand Total | B91: 5324
